Workbook
Name Slicer_Department: #N/A
Name Slicer_Region: #N/A
Name Slicer_Status: #N/A

Sheet Raw Data
A1: Employee_ID | B1: First_Name | C1: Last_Name | D1: Name | E1: Age | F1: Department_Region | G1: Status | H1: Join_Date | I1: Salary | J1: Email | K1: Phone | L1: Performance_Score | M1: Remote_Work
A2: EMP1001 | B2: Noor | C2: Rashid | D2: Noor Rashid | E2: 26 | F2: Operations-Makkah | G2: Active | H2: 2022/05/07 | I2: 13700 | J2: noor.rashid1@example.com | K2: 056-287-5060 | L2: Needs Improvement | M2: FALSE
A3: EMP1002 | B3: Yara | C3: Hassan | D3: Yara Hassan | E3: 48 | F3: HR-Tabuk | G3: Active | H3: 2019-10-27 | I3: 13100 | J3: yara.hassan2@example.com | K3: 050-965-8839 | L3: Good | M3: FALSE
A4: EMP1003 | B4: Adel | C4: Malik | D4: Adel Malik | E4: 24 | F4: Finance-Jeddah | G4: Active | H4: 02/13/2020 | I4: 8000 | J4: adel.malik3@example.com | K4: 054-653-1834 | L4: Excellent | M4: TRUE
A5: EMP1004 | B5: Salma | C5: Ahmed | D5: Salma Ahmed | E5: 26 | F5: Operations-Madinah | G5: Inactive | H5: 2023-10-19 | I5: 16100 | J5: salma.ahmed4@example.com | K5: 055-112-6913 | L5: Excellent | M5: FALSE
A6: EMP1005 | B6: Khalid | C6: Rashid | D6: Khalid Rashid | E6: 32 | F6: Marketing-Tabuk | G6: Active | H6: 02-09-2023 | I6: 6500 | J6: khalid.rashid5@example.com | K6: 055-446-1937 | L6: Good | M6: TRUE
A7: EMP1005 | B7: Hassan | C7: Nasser | D7: Hassan Nasser | E7: 40 | F7: Finance-Makkah | G7: Active | H7: 2019-05-15 | I7: 11400 | J7: hassan.nasser6@example.com | K7: 053-891-8825 | L7: Good | M7: TRUE
A8: EMP1007 | B8: Amina | C8: Latif | D8: Amina Latif | E8: 40 | F8: Finance-Riyadh | G8: Active | H8: 26-06-2018 | I8: 14700 | J8: amina.latif7@example.com | K8: 057-854-1056 | L8: Good | M8: FALSE
A9: EMP1008 | B9: Majed | C9: Rahman | D9: Majed Rahman | E9: 43 | F9: Sales-Riyadh | G9: Active | H9: 13-04-2021 | I9: N/A | J9: majed.rahman8@example.com | K9: 052-164-2283 | L9: Good | M9: TRUE
A10: EMP1009 | B10: Salma | C10: Hadi | D10: Salma Hadi | E10: 39 | F10: HR-Tabuk | G10: Active | H10: 02/08/2025 | I10: 12100 | J10: salma.hadi9@example.com | K10: 058-578-4503 | L10: Average | M10: FALSE
A11: EMP1010 | B11: Rami | C11: Saeed | D11: Rami Saeed | E11: 43 | F11: HR-Jeddah | G11: active | H11: 27-09-2021 | I11: 6200 | J11: rami.saeed10@example.com | K11: 053-544-6208 | L11: Good | M11: TRUE
A12: EMP1011 | B12: Yusuf | C12: Qureshi | D12: Yusuf Qureshi | E12: 56 | F12: HR-Jeddah | G12: Pending | H12: 07-06-2019 | I12: 5400 | J12: yusuf.qureshi11@example.com | K12: 059-711-9537 | L12: good | M12: FALSE
A13: EMP1012 | B13: Adel | C13: Ali | D13: Adel Ali | F13: Data Analytics-Dammam | G13: Active | H13: 18-05-2021 | I13: 17000 | J13: adel.ali12@example.com | K13: 053-501-4125 | L13: Excellent | M13: FALSE
A14: EMP1013 | B14: Faisal | C14: Jaber | D14: Faisal Jaber | E14: 52 | F14: IT Support-Riyadh | G14: Active | H14: 2023/13/05 | I14: 6000 | J14: faisal.jaber13@example.com | K14: 059-883-1785 | L14: Average | M14: TRUE
A15: EMP1014 | B15: Omar | C15: Hadi | D15: Omar Hadi | E15: 28 | F15: Cloud Tech-Dammam | G15: Active | H15: 2025-09-03 | I15: 16600 | J15: omar.hadi14@example.com | K15: 055-835-9673 | L15: Needs Improvement | M15: FALSE
A16: EMP1015 | B16: Yara | C16: FAROOQ | D16: Yara Farooq | E16: 52 | F16: Operations-Madinah | G16: Active | H16: 08/12/2019 | I16: 9800 | J16: yara.farooq15@example.com | K16: 058-851-4932 | L16: Good | M16: FALSE
A17: EMP1016 | B17: Yusuf | C17: Saeed | D17: Yusuf Saeed | E17: 53 | F17: Operations-Madinah | G17: Active | H17: 2022-11-06 | I17: 8800 | J17: yusuf.saeed16@example.com | K17: 051-639-8562 | L17: Good | M17: TRUE
A18: EMP1017 | B18: Salma | C18: Malik | D18: Salma Malik | E18: 37 | F18: Operations-Makkah | G18: Inactive | H18: 04-02-2022 | I18: 18700 | J18: salma.malik17@example.com | K18: 056-734-5239 | L18: Good | M18: TRUE
A19: EMP1018 | B19: Yara | C19: Saleh | D19: Yara Saleh | E19: 27 | F19: Marketing-Makkah | G19: Pending | H19: 2018/08/24 | I19: 8000 | J19: yara.saleh18@example.com | K19: 051-838-1380 | L19: Average | M19: TRUE
A20: EMP1019 | B20: Yara | C20: Kamal | D20: Yara Kamal | E20: 49 | F20: Finance-Makkah | G20: Active | H20: 2022/08/11 | I20: 11400 | J20: yara.kamal19@example.com | K20: 051-227-3923 | L20: Average | M20: TRUE
A21: EMP1020 | B21: Khalid | C21: Rahman | D21: Khalid Rahman | E21: 45 | F21: Cloud Tech -Riyadh | G21: Active | H21: 2022/08/27 | I21: 12600 | J21: khalid.rahman20@example.com | K21: 057-445-5599 | L21: Average | M21: TRUE
A22: EMP1021 | B22: Lina | C22: Farooq | D22: Lina Farooq | E22: 54 | F22: Data Analytics-Makkah | G22: Active | H22: 2022-04-25 | I22: 15200 | J22: lina.farooq21@example.com | K22: 056-501-7308 | L22: Needs Improvement | M22: FALSE
A23: EMP1022 | B23: Zaid | C23: Saleh | D23: Zaid Saleh | E23: 34 | F23: Cloud Tech-Dammam | G23: Active | H23: 2019-02-05 | I23: 17200 | J23: zaid.saleh22@example.com | K23: 0551234567 | L23: Good | M23: TRUE
A24: EMP1023 | B24: Yusuf | C24: Hassan | D24: Yusuf Hassan | E24: 55 | F24: HR-Riyadh | G24: Active | H24: 2025/03/14 | I24: 8900 | J24: yusuf.hassan23@example.com | K24: 054-617-8986 | L24: Needs Improvement | M24: TRUE
A25: EMP1024 | B25: Hassan | C25: Rashid | D25: Hassan Rashid | E25: 56 | F25: Sales-Makkah | G25: Active | H25: 2019-08-18 | I25: 12500 | J25: hassan.rashid24@example.com | K25: 058-350-1027 | L25: Average | M25: TRUE
A26: EMP1025 | B26: Sami | C26: Hadi | D26: Sami Hadi | E26: 54 | F26: Sales-Riyadh | G26: Active | H26: 14-01-2025 | I26: 17900 | J26: sami.hadi25@example.com | K26: 056-981-1709 | L26: Good | M26: FALSE
A27: EMP1026 | B27: Noura | C27: Hadi | D27: Noura Hadi | E27: 34 | F27: HR-Madinah | G27: Inactive | H27: 2020-03-17 | I27: 15400 | J27: noura.hadi26@example.com | K27: 057-297-2333 | L27: Average | M27: FALSE
A28: EMP1027 | B28: Khalid | C28: Omar | D28: Khalid Omar | E28: 37 | F28: Operations-Madinah | G28: Active | H28: 12/27/2025 | I28: 14800 | J28: khalid.omar27@example.com | K28: 050-598-7226 | L28: Good | M28: TRUE
A29: EMP1028 | B29: Yusuf | C29: Saeed | D29: Yusuf WrongLast | E29: 25 | F29: Finance-Riyadh | G29: Active | H29: 17-12-2022 | I29: 14600 | J29: yusuf.saeed28@example.com | K29: 058-675-8809 | L29: Needs Improvement | M29: TRUE
A30: EMP1029 | B30: Zaid | C30: Ahmed | D30: Zaid Ahmed | E30: 38 | F30: Sales-Madinah | G30: Inactive | H30: 2022-02-23 | I30: 5100 | J30: zaid.ahmed29@example.com | K30: 058-133-9082 | L30: Needs Improvement | M30: TRUE
A31: EMP1030 | B31: Bilal | C31: Hassan | D31: Bilal Hassan | E31: 59 | F31: Data Analytics-Makkah | G31: Inactive | H31: 03/06/2022 | J31: bilal.hassan30@example.com | K31: 057-791-9081 | L31: Average | M31: FALSE
A32: EMP1031 | B32: Rami | C32: Hadi | D32: Rami Hadi | E32: 52 | F32: HR-Madinah | G32: Active | H32: 21-08-2019 | I32: 5300 | J32: rami.hadi31@example.com | K32: 059-953-7162 | L32: Good | M32: TRUE
A33: EMP1032 | B33: Rami | C33: Jaber | D33: rami jaber | E33: 53 | F33: IT Support-Jeddah | G33: Inactive | H33: 10/23/2022 | I33: 6700 | J33: rami.jaber32@example.com | K33: 055-314-4561 | L33: Good | M33: TRUE
A34: EMP1033 | B34: Bilal | C34: Ali | D34: Bilal Ali | E34: 53 | F34: HR-Riyadh | G34: Active | H34: 01/24/2021 | I34: 7800 | J34: bilal.ali33@example.com | K34: 051-602-7917 | L34: Excellent | M34: TRUE
A35: EMP1034 | B35: Faisal | C35: Aziz | D35: Faisal Aziz | E35: 50 | F35: HR-Tabuk | G35: Active | H35: 2023-07-17 | I35: 7200 | J35: faisal.aziz34@example.com | K35: 054-795-7388 | L35: Excellent | M35: FALSE
A36: EMP1035 | B36: Sami | C36: Omar | D36: Sami Omar | E36: 28 | F36: IT Support-Riyadh | G36: Active | H36: not recorded | I36: 16000 | J36: sami.omar35@example.com | K36: 057-298-3787 | L36: Excellent | M36: TRUE
A37: EMP1036 | B37: Amina | C37: Ahmed | D37: Amina Ahmed | E37: 34 | F37: IT Support-Riyadh | G37: Active | H37: 28-05-2021 | I37: 10700 | J37: amina.ahmed36@example.com | K37: 052-178-2550 | L37: Good | M37: TRUE
A38: EMP1037 | B38: Reem | C38: Omar | D38: Reem Omar | E38: 26 | F38: Cloud Tech-Tabuk | G38: Active | H38: 10/02/2022 | I38: 18000 | J38: reem.omar37@example.com | K38: 052-332-1612 | L38: Good | M38: TRUE
A39: EMP1038 | B39: Dina | C39: Ali | D39: Dina Ali | F39: Cloud Tech-Madinah | G39: Inactive | H39: 2023-11-10 | I39: 14900 | J39: dina.ali38@example.com | K39: 056-374-7622 | L39: Average | M39: TRUE
A40: EMP1039 | B40: Huda | C40: Hadi | D40: Huda Hadi | E40: 37 | F40: Cloud Tech-Jeddah | G40: Active | H40: 01/15/2018 | I40: 16700 | J40: huda.hadi39@example.com | K40: 052-864-2084 | L40: Needs Improvement | M40: FALSE
...

Sheet CleanData
A1: Employee_ID | B1: First_Name | C1: Last_Name | D1: Age | E1: Department | F1: Region | G1: Status | H1: Join_Date | I1: Salary | J1: Email | K1: Phone | L1: Performance_Score | M1: Remote_Work | N1: HR_Flag | O1: Priority_Review
A2: EMP1001 | B2: Noor | C2: Rashid | D2: 26 | E2: Operations | F2: Makkah | G2: Active | H2: 44688 | I2: 13700 | J2: noor.rashid1@example.com | K2: 056-287-5060 | L2: Needs Improvement | M2: FALSE | N2: =IF(OR(CleanEmployeeData[[#This Row],[Status]]="Pending",CleanEmployeeData[[#This Row],[Performance_Score]]="Needs Improvement"),"Needs Attention","Normal") -> Needs Attention | O2: =IF(AND(CleanEmployeeData[[#This Row],[Status]]="Active",CleanEmployeeData[[#This Row],[Performance_Score]]="Needs Improvement"),"Priority Review","No") -> Priority Review
A3: EMP1002 | B3: Yara | C3: Hassan | D3: 48 | E3: HR | F3: Tabuk | G3: Active | H3: 43765 | I3: 13100 | J3: yara.hassan2@example.com | K3: 050-965-8839 | L3: Good | M3: FALSE | N3: =IF(OR(CleanEmployeeData[[#This Row],[Status]]="Pending",CleanEmployeeData[[#This Row],[Performance_Score]]="Needs Improvement"),"Needs Attention","Normal") -> Normal | O3: =IF(AND(CleanEmployeeData[[#This Row],[Status]]="Active",CleanEmployeeData[[#This Row],[Performance_Score]]="Needs Improvement"),"Priority Review","No") -> No
A4: EMP1003 | B4: Adel | C4: Malik | D4: 24 | E4: Finance | F4: Jeddah | G4: Active | H4: 43874 | I4: 8000 | J4: adel.malik3@example.com | K4: 054-653-1834 | L4: Excellent | M4: TRUE | N4: =IF(OR(CleanEmployeeData[[#This Row],[Status]]="Pending",CleanEmployeeData[[#This Row],[Performance_Score]]="Needs Improvement"),"Needs Attention","Normal") -> Normal | O4: =IF(AND(CleanEmployeeData[[#This Row],[Status]]="Active",CleanEmployeeData[[#This Row],[Performance_Score]]="Needs Improvement"),"Priority Review","No") -> No
A5: EMP1004 | B5: Salma | C5: Ahmed | D5: 26 | E5: Operations | F5: Madinah | G5: Inactive | H5: 45218 | I5: 16100 | J5: salma.ahmed4@example.com | K5: 055-112-6913 | L5: Excellent | M5: FALSE | N5: =IF(OR(CleanEmployeeData[[#This Row],[Status]]="Pending",CleanEmployeeData[[#This Row],[Performance_Score]]="Needs Improvement"),"Needs Attention","Normal") -> Normal | O5: =IF(AND(CleanEmployeeData[[#This Row],[Status]]="Active",CleanEmployeeData[[#This Row],[Performance_Score]]="Needs Improvement"),"Priority Review","No") -> No
A6: EMP1005 | B6: Khalid | C6: Rashid | D6: 32 | E6: Marketing | F6: Tabuk | G6: Active | H6: 44966 | I6: 6500 | J6: khalid.rashid5@example.com | K6: 055-446-1937 | L6: Good | M6: TRUE | N6: =IF(OR(CleanEmployeeData[[#This Row],[Status]]="Pending",CleanEmployeeData[[#This Row],[Performance_Score]]="Needs Improvement"),"Needs Attention","Normal") -> Normal | O6: =IF(AND(CleanEmployeeData[[#This Row],[Status]]="Active",CleanEmployeeData[[#This Row],[Performance_Score]]="Needs Improvement"),"Priority Review","No") -> No
A7: EMP1007 | B7: Amina | C7: Latif | D7: 40 | E7: Finance | F7: Riyadh | G7: Active | I7: 14700 | J7: amina.latif7@example.com | K7: 057-854-1056 | L7: Good | M7: FALSE | N7: =IF(OR(CleanEmployeeData[[#This Row],[Status]]="Pending",CleanEmployeeData[[#This Row],[Performance_Score]]="Needs Improvement"),"Needs Attention","Normal") -> Normal | O7: =IF(AND(CleanEmployeeData[[#This Row],[Status]]="Active",CleanEmployeeData[[#This Row],[Performance_Score]]="Needs Improvement"),"Priority Review","No") -> No
A8: EMP1008 | B8: Majed | C8: Rahman | D8: 43 | E8: Sales | F8: Riyadh | G8: Active | J8: majed.rahman8@example.com | K8: 052-164-2283 | L8: Good | M8: TRUE | N8: =IF(OR(CleanEmployeeData[[#This Row],[Status]]="Pending",CleanEmployeeData[[#This Row],[Performance_Score]]="Needs Improvement"),"Needs Attention","Normal") -> Normal | O8: =IF(AND(CleanEmployeeData[[#This Row],[Status]]="Active",CleanEmployeeData[[#This Row],[Performance_Score]]="Needs Improvement"),"Priority Review","No") -> No
A9: EMP1009 | B9: Salma | C9: Hadi | D9: 39 | E9: HR | F9: Tabuk | G9: Active | H9: 45696 | I9: 12100 | J9: salma.hadi9@example.com | K9: 058-578-4503 | L9: Average | M9: FALSE | N9: =IF(OR(CleanEmployeeData[[#This Row],[Status]]="Pending",CleanEmployeeData[[#This Row],[Performance_Score]]="Needs Improvement"),"Needs Attention","Normal") -> Normal | O9: =IF(AND(CleanEmployeeData[[#This Row],[Status]]="Active",CleanEmployeeData[[#This Row],[Performance_Score]]="Needs Improvement"),"Priority Review","No") -> No
A10: EMP1010 | B10: Rami | C10: Saeed | D10: 43 | E10: HR | F10: Jeddah | G10: Active | I10: 6200 | J10: rami.saeed10@example.com | K10: 053-544-6208 | L10: Good | M10: TRUE | N10: =IF(OR(CleanEmployeeData[[#This Row],[Status]]="Pending",CleanEmployeeData[[#This Row],[Performance_Score]]="Needs Improvement"),"Needs Attention","Normal") -> Normal | O10: =IF(AND(CleanEmployeeData[[#This Row],[Status]]="Active",CleanEmployeeData[[#This Row],[Performance_Score]]="Needs Improvement"),"Priority Review","No") -> No
A11: EMP1011 | B11: Yusuf | C11: Qureshi | D11: 56 | E11: HR | F11: Jeddah | G11: Pending | H11: 43652 | I11: 5400 | J11: yusuf.qureshi11@example.com | K11: 059-711-9537 | L11: Good | M11: FALSE | N11: =IF(OR(CleanEmployeeData[[#This Row],[Status]]="Pending",CleanEmployeeData[[#This Row],[Performance_Score]]="Needs Improvement"),"Needs Attention","Normal") -> Needs Attention | O11: =IF(AND(CleanEmployeeData[[#This Row],[Status]]="Active",CleanEmployeeData[[#This Row],[Performance_Score]]="Needs Improvement"),"Priority Review","No") -> No
A12: EMP1012 | B12: Adel | C12: Ali | E12: Data Analytics | F12: Dammam | G12: Active | I12: 17000 | J12: adel.ali12@example.com | K12: 053-501-4125 | L12: Excellent | M12: FALSE | N12: =IF(OR(CleanEmployeeData[[#This Row],[Status]]="Pending",CleanEmployeeData[[#This Row],[Performance_Score]]="Needs Improvement"),"Needs Attention","Normal") -> Normal | O12: =IF(AND(CleanEmployeeData[[#This Row],[Status]]="Active",CleanEmployeeData[[#This Row],[Performance_Score]]="Needs Improvement"),"Priority Review","No") -> No
A13: EMP1013 | B13: Faisal | C13: Jaber | D13: 52 | E13: IT Support | F13: Riyadh | G13: Active | I13: 6000 | J13: faisal.jaber13@example.com | K13: 059-883-1785 | L13: Average | M13: TRUE | N13: =IF(OR(CleanEmployeeData[[#This Row],[Status]]="Pending",CleanEmployeeData[[#This Row],[Performance_Score]]="Needs Improvement"),"Needs Attention","Normal") -> Normal | O13: =IF(AND(CleanEmployeeData[[#This Row],[Status]]="Active",CleanEmployeeData[[#This Row],[Performance_Score]]="Needs Improvement"),"Priority Review","No") -> No
A14: EMP1014 | B14: Omar | C14: Hadi | D14: 28 | E14: Cloud Tech | F14: Dammam | G14: Active | H14: 45903 | I14: 16600 | J14: omar.hadi14@example.com | K14: 055-835-9673 | L14: Needs Improvement | M14: FALSE | N14: =IF(OR(CleanEmployeeData[[#This Row],[Status]]="Pending",CleanEmployeeData[[#This Row],[Performance_Score]]="Needs Improvement"),"Needs Attention","Normal") -> Needs Attention | O14: =IF(AND(CleanEmployeeData[[#This Row],[Status]]="Active",CleanEmployeeData[[#This Row],[Performance_Score]]="Needs Improvement"),"Priority Review","No") -> Priority Review
A15: EMP1015 | B15: Yara | C15: Farooq | D15: 52 | E15: Operations | F15: Madinah | G15: Active | H15: 43689 | I15: 9800 | J15: yara.farooq15@example.com | K15: 058-851-4932 | L15: Good | M15: FALSE | N15: =IF(OR(CleanEmployeeData[[#This Row],[Status]]="Pending",CleanEmployeeData[[#This Row],[Performance_Score]]="Needs Improvement"),"Needs Attention","Normal") -> Normal | O15: =IF(AND(CleanEmployeeData[[#This Row],[Status]]="Active",CleanEmployeeData[[#This Row],[Performance_Score]]="Needs Improvement"),"Priority Review","No") -> No
A16: EMP1016 | B16: Yusuf | C16: Saeed | D16: 53 | E16: Operations | F16: Madinah | G16: Active | H16: 44871 | I16: 8800 | J16: yusuf.saeed16@example.com | K16: 051-639-8562 | L16: Good | M16: TRUE | N16: =IF(OR(CleanEmployeeData[[#This Row],[Status]]="Pending",CleanEmployeeData[[#This Row],[Performance_Score]]="Needs Improvement"),"Needs Attention","Normal") -> Normal | O16: =IF(AND(CleanEmployeeData[[#This Row],[Status]]="Active",CleanEmployeeData[[#This Row],[Performance_Score]]="Needs Improvement"),"Priority Review","No") -> No
A17: EMP1017 | B17: Salma | C17: Malik | D17: 37 | E17: Operations | F17: Makkah | G17: Inactive | H17: 44653 | I17: 18700 | J17: salma.malik17@example.com | K17: 056-734-5239 | L17: Good | M17: TRUE | N17: =IF(OR(CleanEmployeeData[[#This Row],[Status]]="Pending",CleanEmployeeData[[#This Row],[Performance_Score]]="Needs Improvement"),"Needs Attention","Normal") -> Normal | O17: =IF(AND(CleanEmployeeData[[#This Row],[Status]]="Active",CleanEmployeeData[[#This Row],[Performance_Score]]="Needs Improvement"),"Priority Review","No") -> No
A18: EMP1018 | B18: Yara | C18: Saleh | D18: 27 | E18: Marketing | F18: Makkah | G18: Pending | H18: 43336 | I18: 8000 | J18: yara.saleh18@example.com | K18: 051-838-1380 | L18: Average | M18: TRUE | N18: =IF(OR(CleanEmployeeData[[#This Row],[Status]]="Pending",CleanEmployeeData[[#This Row],[Performance_Score]]="Needs Improvement"),"Needs Attention","Normal") -> Needs Attention | O18: =IF(AND(CleanEmployeeData[[#This Row],[Status]]="Active",CleanEmployeeData[[#This Row],[Performance_Score]]="Needs Improvement"),"Priority Review","No") -> No
A19: EMP1019 | B19: Yara | C19: Kamal | D19: 49 | E19: Finance | F19: Makkah | G19: Active | H19: 44784 | I19: 11400 | J19: yara.kamal19@example.com | K19: 051-227-3923 | L19: Average | M19: TRUE | N19: =IF(OR(CleanEmployeeData[[#This Row],[Status]]="Pending",CleanEmployeeData[[#This Row],[Performance_Score]]="Needs Improvement"),"Needs Attention","Normal") -> Normal | O19: =IF(AND(CleanEmployeeData[[#This Row],[Status]]="Active",CleanEmployeeData[[#This Row],[Performance_Score]]="Needs Improvement"),"Priority Review","No") -> No
A20: EMP1020 | B20: Khalid | C20: Rahman | D20: 45 | E20: Cloud Tech | F20: Riyadh | G20: Active | H20: 44800 | I20: 12600 | J20: khalid.rahman20@example.com | K20: 057-445-5599 | L20: Average | M20: TRUE | N20: =IF(OR(CleanEmployeeData[[#This Row],[Status]]="Pending",CleanEmployeeData[[#This Row],[Performance_Score]]="Needs Improvement"),"Needs Attention","Normal") -> Normal | O20: =IF(AND(CleanEmployeeData[[#This Row],[Status]]="Active",CleanEmployeeData[[#This Row],[Performance_Score]]="Needs Improvement"),"Priority Review","No") -> No
A21: EMP1021 | B21: Lina | C21: Farooq | D21: 54 | E21: Data Analytics | F21: Makkah | G21: Active | H21: 44676 | I21: 15200 | J21: lina.farooq21@example.com | K21: 056-501-7308 | L21: Needs Improvement | M21: FALSE | N21: =IF(OR(CleanEmployeeData[[#This Row],[Status]]="Pending",CleanEmployeeData[[#This Row],[Performance_Score]]="Needs Improvement"),"Needs Attention","Normal") -> Needs Attention | O21: =IF(AND(CleanEmployeeData[[#This Row],[Status]]="Active",CleanEmployeeData[[#This Row],[Performance_Score]]="Needs Improvement"),"Priority Review","No") -> Priority Review
A22: EMP1022 | B22: Zaid | C22: Saleh | D22: 34 | E22: Cloud Tech | F22: Dammam | G22: Active | H22: 43501 | I22: 17200 | J22: zaid.saleh22@example.com | K22: 0551234567 | L22: Good | M22: TRUE | N22: =IF(OR(CleanEmployeeData[[#This Row],[Status]]="Pending",CleanEmployeeData[[#This Row],[Performance_Score]]="Needs Improvement"),"Needs Attention","Normal") -> Normal | O22: =IF(AND(CleanEmployeeData[[#This Row],[Status]]="Active",CleanEmployeeData[[#This Row],[Performance_Score]]="Needs Improvement"),"Priority Review","No") -> No
A23: EMP1023 | B23: Yusuf | C23: Hassan | D23: 55 | E23: HR | F23: Riyadh | G23: Active | H23: 45730 | I23: 8900 | J23: yusuf.hassan23@example.com | K23: 054-617-8986 | L23: Needs Improvement | M23: TRUE | N23: =IF(OR(CleanEmployeeData[[#This Row],[Status]]="Pending",CleanEmployeeData[[#This Row],[Performance_Score]]="Needs Improvement"),"Needs Attention","Normal") -> Needs Attention | O23: =IF(AND(CleanEmployeeData[[#This Row],[Status]]="Active",CleanEmployeeData[[#This Row],[Performance_Score]]="Needs Improvement"),"Priority Review","No") -> Priority Review
A24: EMP1024 | B24: Hassan | C24: Rashid | D24: 56 | E24: Sales | F24: Makkah | G24: Active | H24: 43695 | I24: 12500 | J24: hassan.rashid24@example.com | K24: 058-350-1027 | L24: Average | M24: TRUE | N24: =IF(OR(CleanEmployeeData[[#This Row],[Status]]="Pending",CleanEmployeeData[[#This Row],[Performance_Score]]="Needs Improvement"),"Needs Attention","Normal") -> Normal | O24: =IF(AND(CleanEmployeeData[[#This Row],[Status]]="Active",CleanEmployeeData[[#This Row],[Performance_Score]]="Needs Improvement"),"Priority Review","No") -> No
A25: EMP1025 | B25: Sami | C25: Hadi | D25: 54 | E25: Sales | F25: Riyadh | G25: Active | I25: 17900 | J25: sami.hadi25@example.com | K25: 056-981-1709 | L25: Good | M25: FALSE | N25: =IF(OR(CleanEmployeeData[[#This Row],[Status]]="Pending",CleanEmployeeData[[#This Row],[Performance_Score]]="Needs Improvement"),"Needs Attention","Normal") -> Normal | O25: =IF(AND(CleanEmployeeData[[#This Row],[Status]]="Active",CleanEmployeeData[[#This Row],[Performance_Score]]="Needs Improvement"),"Priority Review","No") -> No
A26: EMP1026 | B26: Noura | C26: Hadi | D26: 34 | E26: HR | F26: Madinah | G26: Inactive | H26: 43907 | I26: 15400 | J26: noura.hadi26@example.com | K26: 057-297-2333 | L26: Average | M26: FALSE | N26: =IF(OR(CleanEmployeeData[[#This Row],[Status]]="Pending",CleanEmployeeData[[#This Row],[Performance_Score]]="Needs Improvement"),"Needs Attention","Normal") -> Normal | O26: =IF(AND(CleanEmployeeData[[#This Row],[Status]]="Active",CleanEmployeeData[[#This Row],[Performance_Score]]="Needs Improvement"),"Priority Review","No") -> No
A27: EMP1027 | B27: Khalid | C27: Omar | D27: 37 | E27: Operations | F27: Madinah | G27: Active | H27: 46018 | I27: 14800 | J27: khalid.omar27@example.com | K27: 050-598-7226 | L27: Good | M27: TRUE | N27: =IF(OR(CleanEmployeeData[[#This Row],[Status]]="Pending",CleanEmployeeData[[#This Row],[Performance_Score]]="Needs Improvement"),"Needs Attention","Normal") -> Normal | O27: =IF(AND(CleanEmployeeData[[#This Row],[Status]]="Active",CleanEmployeeData[[#This Row],[Performance_Score]]="Needs Improvement"),"Priority Review","No") -> No
A28: EMP1028 | B28: Yusuf | C28: Saeed | D28: 25 | E28: Finance | F28: Riyadh | G28: Active | I28: 14600 | J28: yusuf.saeed28@example.com | K28: 058-675-8809 | L28: Needs Improvement | M28: TRUE | N28: =IF(OR(CleanEmployeeData[[#This Row],[Status]]="Pending",CleanEmployeeData[[#This Row],[Performance_Score]]="Needs Improvement"),"Needs Attention","Normal") -> Needs Attention | O28: =IF(AND(CleanEmployeeData[[#This Row],[Status]]="Active",CleanEmployeeData[[#This Row],[Performance_Score]]="Needs Improvement"),"Priority Review","No") -> Priority Review
A29: EMP1029 | B29: Zaid | C29: Ahmed | D29: 38 | E29: Sales | F29: Madinah | G29: Inactive | H29: 44615 | I29: 5100 | J29: zaid.ahmed29@example.com | K29: 058-133-9082 | L29: Needs Improvement | M29: TRUE | N29: =IF(OR(CleanEmployeeData[[#This Row],[Status]]="Pending",CleanEmployeeData[[#This Row],[Performance_Score]]="Needs Improvement"),"Needs Attention","Normal") -> Needs Attention | O29: =IF(AND(CleanEmployeeData[[#This Row],[Status]]="Active",CleanEmployeeData[[#This Row],[Performance_Score]]="Needs Improvement"),"Priority Review","No") -> No
A30: EMP1030 | B30: Bilal | C30: Hassan | D30: 59 | E30: Data Analytics | F30: Makkah | G30: Inactive | H30: 44626 | J30: bilal.hassan30@example.com | K30: 057-791-9081 | L30: Average | M30: FALSE | N30: =IF(OR(CleanEmployeeData[[#This Row],[Status]]="Pending",CleanEmployeeData[[#This Row],[Performance_Score]]="Needs Improvement"),"Needs Attention","Normal") -> Normal | O30: =IF(AND(CleanEmployeeData[[#This Row],[Status]]="Active",CleanEmployeeData[[#This Row],[Performance_Score]]="Needs Improvement"),"Priority Review","No") -> No
A31: EMP1031 | B31: Rami | C31: Hadi | D31: 52 | E31: HR | F31: Madinah | G31: Active | I31: 5300 | J31: rami.hadi31@example.com | K31: 059-953-7162 | L31: Good | M31: TRUE | N31: =IF(OR(CleanEmployeeData[[#This Row],[Status]]="Pending",CleanEmployeeData[[#This Row],[Performance_Score]]="Needs Improvement"),"Needs Attention","Normal") -> Normal | O31: =IF(AND(CleanEmployeeData[[#This Row],[Status]]="Active",CleanEmployeeData[[#This Row],[Performance_Score]]="Needs Improvement"),"Priority Review","No") -> No
A32: EMP1032 | B32: Rami | C32: Jaber | D32: 53 | E32: IT Support | F32: Jeddah | G32: Inactive | H32: 44857 | I32: 6700 | J32: rami.jaber32@example.com | K32: 055-314-4561 | L32: Good | M32: TRUE | N32: =IF(OR(CleanEmployeeData[[#This Row],[Status]]="Pending",CleanEmployeeData[[#This Row],[Performance_Score]]="Needs Improvement"),"Needs Attention","Normal") -> Normal | O32: =IF(AND(CleanEmployeeData[[#This Row],[Status]]="Active",CleanEmployeeData[[#This Row],[Performance_Score]]="Needs Improvement"),"Priority Review","No") -> No
A33: EMP1033 | B33: Bilal | C33: Ali | D33: 53 | E33: HR | F33: Riyadh | G33: Active | H33: 44220 | I33: 7800 | J33: bilal.ali33@example.com | K33: 051-602-7917 | L33: Excellent | M33: TRUE | N33: =IF(OR(CleanEmployeeData[[#This Row],[Status]]="Pending",CleanEmployeeData[[#This Row],[Performance_Score]]="Needs Improvement"),"Needs Attention","Normal") -> Normal | O33: =IF(AND(CleanEmployeeData[[#This Row],[Status]]="Active",CleanEmployeeData[[#This Row],[Performance_Score]]="Needs Improvement"),"Priority Review","No") -> No
A34: EMP1034 | B34: Faisal | C34: Aziz | D34: 50 | E34: HR | F34: Tabuk | G34: Active | H34: 45124 | I34: 7200 | J34: faisal.aziz34@example.com | K34: 054-795-7388 | L34: Excellent | M34: FALSE | N34: =IF(OR(CleanEmployeeData[[#This Row],[Status]]="Pending",CleanEmployeeData[[#This Row],[Performance_Score]]="Needs Improvement"),"Needs Attention","Normal") -> Normal | O34: =IF(AND(CleanEmployeeData[[#This Row],[Status]]="Active",CleanEmployeeData[[#This Row],[Performance_Score]]="Needs Improvement"),"Priority Review","No") -> No
A35: EMP1035 | B35: Sami | C35: Omar | D35: 28 | E35: IT Support | F35: Riyadh | G35: Active | I35: 16000 | J35: sami.omar35@example.com | K35: 057-298-3787 | L35: Excellent | M35: TRUE | N35: =IF(OR(CleanEmployeeData[[#This Row],[Status]]="Pending",CleanEmployeeData[[#This Row],[Performance_Score]]="Needs Improvement"),"Needs Attention","Normal") -> Normal | O35: =IF(AND(CleanEmployeeData[[#This Row],[Status]]="Active",CleanEmployeeData[[#This Row],[Performance_Score]]="Needs Improvement"),"Priority Review","No") -> No
A36: EMP1036 | B36: Amina | C36: Ahmed | D36: 34 | E36: IT Support | F36: Riyadh | G36: Active | I36: 10700 | J36: amina.ahmed36@example.com | K36: 052-178-2550 | L36: Good | M36: TRUE | N36: =IF(OR(CleanEmployeeData[[#This Row],[Status]]="Pending",CleanEmployeeData[[#This Row],[Performance_Score]]="Needs Improvement"),"Needs Attention","Normal") -> Normal | O36: =IF(AND(CleanEmployeeData[[#This Row],[Status]]="Active",CleanEmployeeData[[#This Row],[Performance_Score]]="Needs Improvement"),"Priority Review","No") -> No
A37: EMP1037 | B37: Reem | C37: Omar | D37: 26 | E37: Cloud Tech | F37: Tabuk | G37: Active | H37: 44836 | I37: 18000 | J37: reem.omar37@example.com | K37: 052-332-1612 | L37: Good | M37: TRUE | N37: =IF(OR(CleanEmployeeData[[#This Row],[Status]]="Pending",CleanEmployeeData[[#This Row],[Performance_Score]]="Needs Improvement"),"Needs Attention","Normal") -> Normal | O37: =IF(AND(CleanEmployeeData[[#This Row],[Status]]="Active",CleanEmployeeData[[#This Row],[Performance_Score]]="Needs Improvement"),"Priority Review","No") -> No
A38: EMP1038 | B38: Dina | C38: Ali | E38: Cloud Tech | F38: Madinah | G38: Inactive | H38: 45240 | I38: 14900 | J38: dina.ali38@example.com | K38: 056-374-7622 | L38: Average | M38: TRUE | N38: =IF(OR(CleanEmployeeData[[#This Row],[Status]]="Pending",CleanEmployeeData[[#This Row],[Performance_Score]]="Needs Improvement"),"Needs Attention","Normal") -> Normal | O38: =IF(AND(CleanEmployeeData[[#This Row],[Status]]="Active",CleanEmployeeData[[#This Row],[Performance_Score]]="Needs Improvement"),"Priority Review","No") -> No
A39: EMP1039 | B39: Huda | C39: Hadi | D39: 37 | E39: Cloud Tech | F39: Jeddah | G39: Active | H39: 43115 | I39: 16700 | J39: huda.hadi39@example.com | K39: 052-864-2084 | L39: Needs Improvement | M39: FALSE | N39: =IF(OR(CleanEmployeeData[[#This Row],[Status]]="Pending",CleanEmployeeData[[#This Row],[Performance_Score]]="Needs Improvement"),"Needs Attention","Normal") -> Needs Attention | O39: =IF(AND(CleanEmployeeData[[#This Row],[Status]]="Active",CleanEmployeeData[[#This Row],[Performance_Score]]="Needs Improvement"),"Priority Review","No") -> Priority Review
A40: EMP1040 | B40: Karim | C40: Rahman | D40: 55 | E40: Data Analytics | F40: Jeddah | G40: Active | H40: 45804 | I40: 15400 | J40: karim.rahman40@example.com | K40: 053-763-9531 | L40: Average | M40: TRUE | N40: =IF(OR(CleanEmployeeData[[#This Row],[Status]]="Pending",CleanEmployeeData[[#This Row],[Performance_Score]]="Needs Improvement"),"Needs Attention","Normal") -> Normal | O40: =IF(AND(CleanEmployeeData[[#This Row],[Status]]="Active",CleanEmployeeData[[#This Row],[Performance_Score]]="Needs Improvement"),"Priority Review","No") -> No
...

Sheet Analysis
A1: Workforce Overview | D1: Department Overview | H1: Region Overview | L1: Performance Overview
A2: Total Employees | B2: =COUNTA(CleanData!A:A)-1 -> 69 | D2: Department | E2: Employee Count | F2: Average Salary | H2: Region Overview | I2: Employee Count | J2: Average Salary | L2: Performance Rating | M2: Employee Count
A3: Active Employees | B3: =COUNTIF(CleanData!G:G,"Active") -> 47 | D3: Data Analytics | E3: =COUNTIF(CleanData!E:E,D3) -> 8 | F3: =AVERAGEIF(CleanData!E:E,Analysis!D3,CleanData!I:I) -> 14685.714 | H3: Riyadh | I3: =COUNTIF(CleanData!F:F,Analysis!H3) -> 14 | J3: =AVERAGEIF(CleanData!F:F,Analysis!H3,CleanData!I:I) -> 11784.615 | L3: Excellent | M3: =COUNTIF(CleanData!L:L,Analysis!L3) -> 12
A4: Inactive Employees | B4: =COUNTIF(CleanData!G:G,"Inactive") -> 15 | D4: Finance | E4: =COUNTIF(CleanData!E:E,D4) -> 7 | F4: =AVERAGEIF(CleanData!E:E,Analysis!D4,CleanData!I:I) -> 10614.286 | H4: Jeddah | I4: =COUNTIF(CleanData!F:F,Analysis!H4) -> 17 | J4: =AVERAGEIF(CleanData!F:F,Analysis!H4,CleanData!I:I) -> 10911.765 | L4: Average | M4: =COUNTIF(CleanData!L:L,Analysis!L4) -> 21
A5: Pending Employees | B5: =COUNTIF(CleanData!G:G,"Pending") -> 7 | D5: Cloud Tech | E5: =COUNTIF(CleanData!E:E,D5) -> 9 | F5: =AVERAGEIF(CleanData!E:E,Analysis!D5,CleanData!I:I) -> 15555.556 | H5: Dammam | I5: =COUNTIF(CleanData!F:F,Analysis!H5) -> 7 | J5: =AVERAGEIF(CleanData!F:F,Analysis!H5,CleanData!I:I) -> 15816.667 | L5: Good | M5: =COUNTIF(CleanData!L:L,Analysis!L5) -> 24
D6: HR | E6: =COUNTIF(CleanData!E:E,D6) -> 9 | F6: =AVERAGEIF(CleanData!E:E,Analysis!D6,CleanData!I:I) -> 9044.4444 | H6: Madinah | I6: =COUNTIF(CleanData!F:F,Analysis!H6) -> 11 | J6: =AVERAGEIF(CleanData!F:F,Analysis!H6,CleanData!I:I) -> 11127.273 | L6: Needs Improvement | M6: =COUNTIF(CleanData!L:L,Analysis!L6) -> 12
D7: IT Support | E7: =COUNTIF(CleanData!E:E,D7) -> 7 | F7: =AVERAGEIF(CleanData!E:E,Analysis!D7,CleanData!I:I) -> 10085.714 | H7: Makkah | I7: =COUNTIF(CleanData!F:F,Analysis!H7) -> 12 | J7: =AVERAGEIF(CleanData!F:F,Analysis!H7,CleanData!I:I) -> 15311.818
A8: Salary Overview | D8: Marketing | E8: =COUNTIF(CleanData!E:E,D8) -> 9 | F8: =AVERAGEIF(CleanData!E:E,Analysis!D8,CleanData!I:I) -> 12870 | H8: Tabuk | I8: =COUNTIF(CleanData!F:F,Analysis!H8) -> 8 | J8: =AVERAGEIF(CleanData!F:F,Analysis!H8,CleanData!I:I) -> 12537.5
A9: Total Salary | B9: =SUM(CleanData!I:I) -> 824730 | D9: Operations | E9: =COUNTIF(CleanData!E:E,D9) -> 9 | F9: =AVERAGEIF(CleanData!E:E,Analysis!D9,CleanData!I:I) -> 13066.667
A10: Average Salary | B10: =AVERAGE(CleanData!I:I) -> 12495.909 | D10: Sales | E10: =COUNTIF(CleanData!E:E,D10) -> 11 | F10: =AVERAGEIF(CleanData!E:E,Analysis!D10,CleanData!I:I) -> 13577.778
A11: Highest Salary | B11: =MAX(CleanData!I:I) -> 47330
A12: Lowest Salary | B12: =MIN(CleanData!I:I) -> 5000 | D12: Department Insights | H12: Region Insights | L12: Performance Insights
A13: Average Salary — Active Employees | B13: =AVERAGEIF(CleanData!G:G,"Active",CleanData!I:I) -> 12043.478 | D13: Department with Most Employees | E13: =_xlfn.XLOOKUP(MAX(E3:E10),E3:E10,D3:D10) -> Sales | H13: Region with Most Employees | I13: =_xlfn.XLOOKUP(MAX(I3:I8),I3:I8,H3:H8) -> Jeddah | L13: Most Common Performance Rating | M13: =_xlfn.XLOOKUP(MAX(M3:M6),M3:M6,L3:L6) -> Good
A14: Average Salary — Inactive Employees | B14: =AVERAGEIF(CleanData!G:G,"Inactive",CleanData!I:I) -> 13257.143 | D14: Department with Highest Average Salary | E14: =_xlfn.XLOOKUP(MAX(F3:F10),F3:F10,D3:D10) -> Cloud Tech | H14: Region with Highest Average Salary | I14: =_xlfn.XLOOKUP(MAX(J3:J8),J3:J8,H3:H8) -> Dammam
A15: Average Salary — Pending Employees | B15: =AVERAGEIF(CleanData!G:G,"Pending",CleanData!I:I) -> 14188.333 | D15: Department with Lowest Average Salary | E15: =_xlfn.XLOOKUP(MIN(F3:F10),F3:F10,D3:D10) -> HR
A18: Age & Work Arrangement
A19: Average Employee Age | B19: =AVERAGE(CleanData!D:D) -> 40.865672
A20: Youngest Employee Age | B20: =MIN(CleanData!D:D) -> 22
A21: Oldest Employee Age | B21: =MAX(CleanData!D:D) -> 59
A22: Remote Employees | B22: =COUNTIF(CleanData!M:M,"TRUE") -> 40
A23: Non-Remote Employees | B23: =COUNTIF(CleanData!M:M,"FALSE") -> 28
A28: Department Status Analysis
A29: Department | B29: Active | C29: Inactive | D29: Pending
A30: Data Analytics | B30: =COUNTIFS(CleanData!$E:$E,Analysis!$A30,CleanData!$G:$G,Analysis!B$29) -> 6 | C30: =COUNTIFS(CleanData!$E:$E,Analysis!$A30,CleanData!$G:$G,Analysis!C$29) -> 2 | D30: =COUNTIFS(CleanData!$E:$E,Analysis!$A30,CleanData!$G:$G,Analysis!D$29) -> 0
A31: Finance | B31: =COUNTIFS(CleanData!$E:$E,Analysis!$A31,CleanData!$G:$G,Analysis!B$29) -> 6 | C31: =COUNTIFS(CleanData!$E:$E,Analysis!$A31,CleanData!$G:$G,Analysis!C$29) -> 0 | D31: =COUNTIFS(CleanData!$E:$E,Analysis!$A31,CleanData!$G:$G,Analysis!D$29) -> 1
A32: Cloud Tech | B32: =COUNTIFS(CleanData!$E:$E,Analysis!$A32,CleanData!$G:$G,Analysis!B$29) -> 8 | C32: =COUNTIFS(CleanData!$E:$E,Analysis!$A32,CleanData!$G:$G,Analysis!C$29) -> 1 | D32: =COUNTIFS(CleanData!$E:$E,Analysis!$A32,CleanData!$G:$G,Analysis!D$29) -> 0
A33: HR | B33: =COUNTIFS(CleanData!$E:$E,Analysis!$A33,CleanData!$G:$G,Analysis!B$29) -> 7 | C33: =COUNTIFS(CleanData!$E:$E,Analysis!$A33,CleanData!$G:$G,Analysis!C$29) -> 1 | D33: =COUNTIFS(CleanData!$E:$E,Analysis!$A33,CleanData!$G:$G,Analysis!D$29) -> 1
A34: IT Support | B34: =COUNTIFS(CleanData!$E:$E,Analysis!$A34,CleanData!$G:$G,Analysis!B$29) -> 5 | C34: =COUNTIFS(CleanData!$E:$E,Analysis!$A34,CleanData!$G:$G,Analysis!C$29) -> 2 | D34: =COUNTIFS(CleanData!$E:$E,Analysis!$A34,CleanData!$G:$G,Analysis!D$29) -> 0
A35: Marketing | B35: =COUNTIFS(CleanData!$E:$E,Analysis!$A35,CleanData!$G:$G,Analysis!B$29) -> 4 | C35: =COUNTIFS(CleanData!$E:$E,Analysis!$A35,CleanData!$G:$G,Analysis!C$29) -> 2 | D35: =COUNTIFS(CleanData!$E:$E,Analysis!$A35,CleanData!$G:$G,Analysis!D$29) -> 3
A36: Operations | B36: =COUNTIFS(CleanData!$E:$E,Analysis!$A36,CleanData!$G:$G,Analysis!B$29) -> 5 | C36: =COUNTIFS(CleanData!$E:$E,Analysis!$A36,CleanData!$G:$G,Analysis!C$29) -> 3 | D36: =COUNTIFS(CleanData!$E:$E,Analysis!$A36,CleanData!$G:$G,Analysis!D$29) -> 1
A37: Sales | B37: =COUNTIFS(CleanData!$E:$E,Analysis!$A37,CleanData!$G:$G,Analysis!B$29) -> 6 | C37: =COUNTIFS(CleanData!$E:$E,Analysis!$A37,CleanData!$G:$G,Analysis!C$29) -> 4 | D37: =COUNTIFS(CleanData!$E:$E,Analysis!$A37,CleanData!$G:$G,Analysis!D$29) -> 1
A39: Department Salary Analysis
A40: Department | B40: Active | C40: Inactive | D40: Pending
A41: Data Analytics | B41: =IFERROR(AVERAGEIFS(CleanData!$I:$I,CleanData!$E:$E,Analysis!$A41,CleanData!$G:$G,Analysis!B$40),"N/A") -> 15483.333 | C41: =IFERROR(AVERAGEIFS(CleanData!$I:$I,CleanData!$E:$E,Analysis!$A41,CleanData!$G:$G,Analysis!C$40),"N/A") -> 9900 | D41: =IFERROR(AVERAGEIFS(CleanData!$I:$I,CleanData!$E:$E,Analysis!$A41,CleanData!$G:$G,Analysis!D$40),"N/A") -> N/A
A42: Finance | B42: =IFERROR(AVERAGEIFS(CleanData!$I:$I,CleanData!$E:$E,Analysis!$A42,CleanData!$G:$G,Analysis!B$40),"N/A") -> 10300 | C42: =IFERROR(AVERAGEIFS(CleanData!$I:$I,CleanData!$E:$E,Analysis!$A42,CleanData!$G:$G,Analysis!C$40),"N/A") -> N/A | D42: =IFERROR(AVERAGEIFS(CleanData!$I:$I,CleanData!$E:$E,Analysis!$A42,CleanData!$G:$G,Analysis!D$40),"N/A") -> 12500
A43: Cloud Tech | B43: =IFERROR(AVERAGEIFS(CleanData!$I:$I,CleanData!$E:$E,Analysis!$A43,CleanData!$G:$G,Analysis!B$40),"N/A") -> 15637.5 | C43: =IFERROR(AVERAGEIFS(CleanData!$I:$I,CleanData!$E:$E,Analysis!$A43,CleanData!$G:$G,Analysis!C$40),"N/A") -> 14900 | D43: =IFERROR(AVERAGEIFS(CleanData!$I:$I,CleanData!$E:$E,Analysis!$A43,CleanData!$G:$G,Analysis!D$40),"N/A") -> N/A
A44: HR | B44: =IFERROR(AVERAGEIFS(CleanData!$I:$I,CleanData!$E:$E,Analysis!$A44,CleanData!$G:$G,Analysis!B$40),"N/A") -> 8657.1429 | C44: =IFERROR(AVERAGEIFS(CleanData!$I:$I,CleanData!$E:$E,Analysis!$A44,CleanData!$G:$G,Analysis!C$40),"N/A") -> 15400 | D44: =IFERROR(AVERAGEIFS(CleanData!$I:$I,CleanData!$E:$E,Analysis!$A44,CleanData!$G:$G,Analysis!D$40),"N/A") -> 5400
A45: IT Support | B45: =IFERROR(AVERAGEIFS(CleanData!$I:$I,CleanData!$E:$E,Analysis!$A45,CleanData!$G:$G,Analysis!B$40),"N/A") -> 10620 | C45: =IFERROR(AVERAGEIFS(CleanData!$I:$I,CleanData!$E:$E,Analysis!$A45,CleanData!$G:$G,Analysis!C$40),"N/A") -> 8750 | D45: =IFERROR(AVERAGEIFS(CleanData!$I:$I,CleanData!$E:$E,Analysis!$A45,CleanData!$G:$G,Analysis!D$40),"N/A") -> N/A
A46: Marketing | B46: =IFERROR(AVERAGEIFS(CleanData!$I:$I,CleanData!$E:$E,Analysis!$A46,CleanData!$G:$G,Analysis!B$40),"N/A") -> 8575 | C46: =IFERROR(AVERAGEIFS(CleanData!$I:$I,CleanData!$E:$E,Analysis!$A46,CleanData!$G:$G,Analysis!C$40),"N/A") -> 10150 | D46: =IFERROR(AVERAGEIFS(CleanData!$I:$I,CleanData!$E:$E,Analysis!$A46,CleanData!$G:$G,Analysis!D$40),"N/A") -> 20410
A47: Operations | B47: =IFERROR(AVERAGEIFS(CleanData!$I:$I,CleanData!$E:$E,Analysis!$A47,CleanData!$G:$G,Analysis!B$40),"N/A") -> 12240 | C47: =IFERROR(AVERAGEIFS(CleanData!$I:$I,CleanData!$E:$E,Analysis!$A47,CleanData!$G:$G,Analysis!C$40),"N/A") -> 16800 | D47: =IFERROR(AVERAGEIFS(CleanData!$I:$I,CleanData!$E:$E,Analysis!$A47,CleanData!$G:$G,Analysis!D$40),"N/A") -> 6000
...

Sheet Pivot Analysis
A1: Row Labels | B1: Count of Employee_ID | G1: Row Labels | H1: Average of Salary | L1: Count of Employee_ID | M1: Column Labels
A2: Cloud Tech | B2: 9 | G2: Cloud Tech | H2: 15555.556 | L2: Row Labels | M2: FALSE | N2: TRUE | O2: (blank) | P2: Grand Total
A3: Data Analytics | B3: 8 | G3: Data Analytics | H3: 14685.714 | L3: Average | M3: 7 | N3: 14 | P3: 21
A4: Finance | B4: 7 | G4: Finance | H4: 10614.286 | L4: Excellent | M4: 5 | N4: 6 | O4: 1 | P4: 12
A5: HR | B5: 9 | G5: HR | H5: 9044.4444 | L5: Good | M5: 10 | N5: 14 | P5: 24
A6: IT Support | B6: 7 | G6: IT Support | H6: 10085.714 | L6: Needs Improvement | M6: 6 | N6: 6 | P6: 12
A7: Marketing | B7: 9 | G7: Marketing | H7: 12870 | L7: Grand Total | M7: 28 | N7: 40 | O7: 1 | P7: 69
A8: Operations | B8: 9 | G8: Operations | H8: 13066.667
A9: Sales | B9: 11 | G9: Sales | H9: 13577.778
A10: Grand Total | B10: 69 | G10: Grand Total | H10: 12495.909

Sheet Dashboard
A1: HR EMPLOYEE ANALYTICS DASHBOARD
D2: Workforce • Salary • Performance • HR Attention
A4: Total Employees | C4: Active Employees | E4: Average Salary | G4: Remote Employees | I4: Needs Attention
A5: =Analysis!B2 -> 69 | C5: =Analysis!B3 -> 47 | E5: =Analysis!B10 -> 12495.909 | G5: =Analysis!B22 -> 40 | I5: =COUNTIF(CleanData!N:N,"Needs Attention") -> 18
A57: Key HR Insights
A58: Sales has the largest workforce with 11 employees.
A59: Cloud Tech has the highest average salary at approximately 15,556.
A60: Jeddah has the highest employee count among all regions.
A61: Good is the most common performance rating with 24 employees.
A62: Remote employees have higher counts in the Good and Average performance categories than non-remote employees.
A63: Data Analytics, Cloud Tech, and Marketing are tied for the highest number of employees flagged as Needs Attention.
