Workbook

Sheet RawData
A1: Customer ID | B1: Customer Name | C1: Email | D1: Phone | E1: City | F1: Country | G1: Registration Date | H1: Order Amount
A2: C001 | B2: john smith | C2: JOHN.SMITH@email.com | D2: 555-123-4567 | E2: new york | F2: USA | G2: 46143 | H2: 250
A3: C002 | B3: mary johnson | C3: mary.johnson@EMAIL.com | D3: 5551234568 | E3: NEW YORK | F3: usa | G3: 46144 | H3: 180
A4: C003 | B4: DAVID WILSON | C4: david.wilson@email.com | D4: 555-234-5678 | E4: chicago | F4: USA | G4: 46147 | H4: 320
A5: C004 | B5: sarah brown | C5: SARAH.BROWN@email.com | D5: 5552345679 | E5: CHICAGO | F5: usa | G5: 46149 | H5: 150
A6: C005 | B6: Michael Davis | C6: michael.davis@email.com | D6: 555-345-6789 | E6: los angeles | F6: USA | G6: 46152 | H6: 450
A7: C006 | B7: emily miller | C7: EMILY.MILLER@email.com | D7: 5553456790 | E7: Los Angeles | F7: usa | G7: 46154 | H7: 210
A8: C007 | B8: James Wilson | C8: james.wilson@email.com | D8: 555-456-7890 | E8: houston | F8: USA | G8: 46157 | H8: 375
A9: C008 | B9: lisa taylor | C9: lisa.taylor@email.com | D9: 5554567891 | E9: HOUSTON | F9: usa | G9: 46160 | H9: 190
A10: C009 | B10: Robert Anderson | C10: ROBERT.ANDERSON@email.com | D10: 555-567-8901 | E10: miami | F10: USA | G10: 46162 | H10: 500
A11: C010 | B11: jennifer thomas | C11: jennifer.thomas@email.com | D11: 5555678902 | E11: MIAMI | F11: usa | G11: 46164 | H11: 275
A12: C011 | B12: john smith | C12: JOHN.SMITH@email.com | D12: 555-123-4567 | E12: new york | F12: USA | G12: 46143 | H12: 250
A13: C012 | B13: william jackson | C13: william.jackson@email.com | D13: 555-678-9012 | E13: dallas | F13: USA | G13: 46167 | H13: 340
A14: C013 | B14: patricia white | C14: PATRICIA.WHITE@email.com | D14: 5556789013 | E14: DALLAS | F14: usa | G14: 46169 | H14: 225
A15: C014 | B15: charles harris | C15: charles.harris@email.com | D15: 555-789-0123 | E15: seattle | F15: USA | G15: 46171 | H15: 410
A16: C015 | B16: linda martin | C16: LINDA.MARTIN@email.com | D16: 5557890124 | E16: SEATTLE | F16: usa | G16: 46172 | H16: 195
A17: C016 | B17: Thomas Clark | C17: thomas.clark@email.com | D17: 555-890-1234 | E17: boston | F17: USA | G17: 46174 | H17: 360
A18: C017 | B18: Susan Lewis | C18: susan.lewis@EMAIL.com | D18: 5558901235 | E18: BOSTON | F18: usa | G18: 46176 | H18: 285
A19: C018 | B19: Christopher Lee | C19: christopher.lee@email.com | D19: 555-901-2345 | E19: denver | F19: USA | G19: 46178 | H19: 420
A20: C019 | B20: Nancy walker | C20: nancy.walker@email.com | D20: 5559012346 | E20: DENVER | F20: USA | G20: 46180 | H20: 175
A21: C020 | B21: Daniel Hall | C21: daniel.hall@email.com | D21: 555-012-3456 | E21: phoenix | F21: usa | G21: 46183 | H21: 390
A22: C021 | B22: Karen Allen | C22: karen.allen@email.com | D22: 5550123457 | E22: PHOENIX | F22: USA | G22: 46185 | H22: 240
A23: C022 | B23: Matthew Young | C23: matthew.young@EMAIL.com | D23: 555-123-4568 | E23: san diego | F23: USA | G23: 46188 | H23: 315
A24: C023 | B24: Betty Hernandez | C24: betty.hernandez@email.com | D24: 5551234569 | E24: SAN DIEGO | F24: usa | G24: 46190 | H24: 200
A25: C024 | B25: Donald King | C25: donald.king@email.com | D25: 555-234-5680 | E25: austin | F25: USA | G25: 46193 | H25: 475
A26: C025 | B26: Lisa Wright | C26: lisa.wright@email.com | D26: 5552345681 | E26: AUSTIN | F26: usa | G26: 46195 | H26: 220
A27: C026 | B27: Mark Lopez | C27: mark.lopez@EMAIL.com | D27: 555-345-6790 | E27: san antonio | F27: USA | G27: 46198 | H27: 330
A28: C027 | B28: Barbara Hill | C28: barbara.hill@email.com | D28: 5553456791 | E28: SAN ANTONIO | F28: usa | G28: 46200 | H28: 185
A29: C028 | B29: Steven Scott | C29: steven.scott@email.com | D29: 555-456-7801 | E29: portland | F29: USA | G29: 46203 | H29: 510
A30: C029 | B30: Dorothy Green | C30: dorothy.green@email.com | D30: 5554567802 | E30: PORTLAND | F30: usa | G30: 46205 | H30: 265
A31: C030 | B31: Joseph Adams | C31: joseph.adams@email.com | D31: 555-567-8912 | E31: ORLANDO | F31: USA | G31: 46208 | H31: 355
A32: C031 | B32: Margaret Baker | C32: margaret.baker@EMAIL.com | D32: 5555678913 | E32: orlando | F32: usa | G32: 46210 | H32: 195
A33: C032 | B33: Edward Nelson | C33: edward.nelson@email.com | D33: 555-678-9023 | E33: atlanta | F33: USA | G33: 46213 | H33: 440
A34: C033 | B34: Jennifer Carter | C34: jennifer.carter@email.com | D34: 5556789024 | E34: ATLANTA | F34: usa | G34: 46215 | H34: 275
A35: C034 | B35: George Mitchell | C35: george.mitchell@email.com | D35: 555-789-0134 | E35: charlotte | F35: USA | G35: 46218 | H35: 310
A36: C035 | B36: Patricia Perez | C36: patricia.perez@email.com | D36: 5557890135 | E36: CHARLOTTE | F36: usa | G36: 46220 | H36: 230
A37: C036 | B37: Richard Roberts | C37: richard.roberts@EMAIL.com | D37: 555-890-1245 | E37: nashville | F37: USA | G37: 46223 | H37: 485
A38: C037 | B38: Linda Turner | C38: linda.turner@email.com | D38: 5558901246 | E38: NASHVILLE | F38: usa | G38: 46225 | H38: 210
A39: C038 | B39: Charles Phillips | C39: charles.phillips@email.com | D39: 555-901-2356 | E39: raleigh | F39: USA | G39: 46228 | H39: 365
A40: C039 | B40: Jessica Campbell | C40: jessica.campbell@email.com | D40: 5559012357 | E40: RALEIGH | F40: usa | G40: 46230 | H40: 195
...

Sheet CleanData
A1: Customer ID | B1: Customer Name | C1: Email | D1: Phone | E1: City | F1: Country | G1: Registration Date | H1: Order Amount
A2: =RawData!A29 -> C028 | B2: =PROPER(TRIM(RawData!B29)) -> Steven Scott | C2: =LOWER(TRIM(RawData!C29)) -> steven.scott@email.com | D2: =TEXT(RawData!D29,"000-000-0000") -> 555-456-7801 | E2: =PROPER(TRIM(RawData!E29)) -> Portland | F2: USA | G2: =RawData!G29 -> 46203 | H2: 600
A3: =RawData!A10 -> C009 | B3: =PROPER(TRIM(RawData!B10)) -> Robert Anderson | C3: =LOWER(TRIM(RawData!C10)) -> robert.anderson@email.com | D3: =TEXT(RawData!D10,"000-000-0000") -> 555-567-8901 | E3: =PROPER(TRIM(RawData!E10)) -> Miami | F3: USA | G3: =RawData!G10 -> 46162 | H3: =RawData!H10 -> 500
A4: =RawData!A37 -> C036 | B4: =PROPER(TRIM(RawData!B37)) -> Richard Roberts | C4: =LOWER(TRIM(RawData!C37)) -> richard.roberts@email.com | D4: =TEXT(RawData!D37,"000-000-0000") -> 555-890-1245 | E4: =PROPER(TRIM(RawData!E37)) -> Nashville | F4: USA | G4: =RawData!G37 -> 46223 | H4: =RawData!H37 -> 485
A5: =RawData!A25 -> C024 | B5: =PROPER(TRIM(RawData!B25)) -> Donald King | C5: =LOWER(TRIM(RawData!C25)) -> donald.king@email.com | D5: =TEXT(RawData!D25,"000-000-0000") -> 555-234-5680 | E5: =PROPER(TRIM(RawData!E25)) -> Austin | F5: USA | G5: =RawData!G25 -> 46193 | H5: =RawData!H25 -> 475
A6: =RawData!A6 -> C005 | B6: =PROPER(TRIM(RawData!B6)) -> Michael Davis | C6: =LOWER(TRIM(RawData!C6)) -> michael.davis@email.com | D6: =TEXT(RawData!D6,"000-000-0000") -> 555-345-6789 | E6: =PROPER(TRIM(RawData!E6)) -> Los Angeles | F6: USA | G6: =RawData!G6 -> 46152 | H6: =RawData!H6 -> 450
A7: =RawData!A33 -> C032 | B7: =PROPER(TRIM(RawData!B33)) -> Edward Nelson | C7: =LOWER(TRIM(RawData!C33)) -> edward.nelson@email.com | D7: =TEXT(RawData!D33,"000-000-0000") -> 555-678-9023 | E7: =PROPER(TRIM(RawData!E33)) -> Atlanta | F7: USA | G7: =RawData!G33 -> 46213 | H7: =RawData!H33 -> 440
A8: =RawData!A41 -> C040 | B8: =PROPER(TRIM(RawData!B41)) -> Daniel Parker | C8: =LOWER(TRIM(RawData!C41)) -> daniel.parker@email.com | D8: =TEXT(RawData!D41,"000-000-0000") -> 555-012-3467 | E8: =PROPER(TRIM(RawData!E41)) -> Phoenix | F8: USA | G8: =RawData!G41 -> 46233 | H8: =RawData!H41 -> 425
A9: =RawData!A19 -> C018 | B9: =PROPER(TRIM(RawData!B19)) -> Christopher Lee | C9: =LOWER(TRIM(RawData!C19)) -> christopher.lee@email.com | D9: =TEXT(RawData!D19,"000-000-0000") -> 555-901-2345 | E9: =PROPER(TRIM(RawData!E19)) -> Denver | F9: USA | G9: =RawData!G19 -> 46178 | H9: =RawData!H19 -> 420
A10: =RawData!A15 -> C014 | B10: =PROPER(TRIM(RawData!B15)) -> Charles Harris | C10: =LOWER(TRIM(RawData!C15)) -> charles.harris@email.com | D10: =TEXT(RawData!D15,"000-000-0000") -> 555-789-0123 | E10: =PROPER(TRIM(RawData!E15)) -> Seattle | F10: USA | G10: =RawData!G15 -> 46171 | H10: =RawData!H15 -> 410
A11: =RawData!A21 -> C020 | B11: =PROPER(TRIM(RawData!B21)) -> Daniel Hall | C11: =LOWER(TRIM(RawData!C21)) -> daniel.hall@email.com | D11: =TEXT(RawData!D21,"000-000-0000") -> 555-012-3456 | E11: =PROPER(TRIM(RawData!E21)) -> Phoenix | F11: USA | G11: =RawData!G21 -> 46183 | H11: =RawData!H21 -> 390
A12: =RawData!A8 -> C007 | B12: =PROPER(TRIM(RawData!B8)) -> James Wilson | C12: =LOWER(TRIM(RawData!C8)) -> james.wilson@email.com | D12: =TEXT(RawData!D8,"000-000-0000") -> 555-456-7890 | E12: =PROPER(TRIM(RawData!E8)) -> Houston | F12: USA | G12: =RawData!G8 -> 46157 | H12: =RawData!H8 -> 375
A13: =RawData!A39 -> C038 | B13: =PROPER(TRIM(RawData!B39)) -> Charles Phillips | C13: =LOWER(TRIM(RawData!C39)) -> charles.phillips@email.com | D13: =TEXT(RawData!D39,"000-000-0000") -> 555-901-2356 | E13: =PROPER(TRIM(RawData!E39)) -> Raleigh | F13: USA | G13: =RawData!G39 -> 46228 | H13: =RawData!H39 -> 365
A14: =RawData!A17 -> C016 | B14: =PROPER(TRIM(RawData!B17)) -> Thomas Clark | C14: =LOWER(TRIM(RawData!C17)) -> thomas.clark@email.com | D14: =TEXT(RawData!D17,"000-000-0000") -> 555-890-1234 | E14: =PROPER(TRIM(RawData!E17)) -> Boston | F14: USA | G14: =RawData!G17 -> 46174 | H14: =RawData!H17 -> 360
A15: =RawData!A31 -> C030 | B15: =PROPER(TRIM(RawData!B31)) -> Joseph Adams | C15: =LOWER(TRIM(RawData!C31)) -> joseph.adams@email.com | D15: =TEXT(RawData!D31,"000-000-0000") -> 555-567-8912 | E15: =PROPER(TRIM(RawData!E31)) -> Orlando | F15: USA | G15: =RawData!G31 -> 46208 | H15: =RawData!H31 -> 355
A16: =RawData!A13 -> C012 | B16: =PROPER(TRIM(RawData!B13)) -> William Jackson | C16: =LOWER(TRIM(RawData!C13)) -> william.jackson@email.com | D16: =TEXT(RawData!D13,"000-000-0000") -> 555-678-9012 | E16: =PROPER(TRIM(RawData!E13)) -> Dallas | F16: USA | G16: =RawData!G13 -> 46167 | H16: =RawData!H13 -> 340
A17: =RawData!A27 -> C026 | B17: =PROPER(TRIM(RawData!B27)) -> Mark Lopez | C17: =LOWER(TRIM(RawData!C27)) -> mark.lopez@email.com | D17: =TEXT(RawData!D27,"000-000-0000") -> 555-345-6790 | E17: =PROPER(TRIM(RawData!E27)) -> San Antonio | F17: USA | G17: =RawData!G27 -> 46198 | H17: =RawData!H27 -> 330
A18: =RawData!A4 -> C003 | B18: =PROPER(TRIM(RawData!B4)) -> David Wilson | C18: =LOWER(TRIM(RawData!C4)) -> david.wilson@email.com | D18: =TEXT(RawData!D4,"000-000-0000") -> 555-234-5678 | E18: =PROPER(TRIM(RawData!E4)) -> Chicago | F18: USA | G18: =RawData!G4 -> 46147 | H18: =RawData!H4 -> 320
A19: =RawData!A23 -> C022 | B19: =PROPER(TRIM(RawData!B23)) -> Matthew Young | C19: =LOWER(TRIM(RawData!C23)) -> matthew.young@email.com | D19: =TEXT(RawData!D23,"000-000-0000") -> 555-123-4568 | E19: =PROPER(TRIM(RawData!E23)) -> San Diego | F19: USA | G19: =RawData!G23 -> 46188 | H19: =RawData!H23 -> 315
A20: =RawData!A35 -> C034 | B20: =PROPER(TRIM(RawData!B35)) -> George Mitchell | C20: =LOWER(TRIM(RawData!C35)) -> george.mitchell@email.com | D20: =TEXT(RawData!D35,"000-000-0000") -> 555-789-0134 | E20: =PROPER(TRIM(RawData!E35)) -> Charlotte | F20: USA | G20: =RawData!G35 -> 46218 | H20: =RawData!H35 -> 310
A21: =RawData!A18 -> C017 | B21: =PROPER(TRIM(RawData!B18)) -> Susan Lewis | C21: =LOWER(TRIM(RawData!C18)) -> susan.lewis@email.com | D21: =TEXT(RawData!D18,"000-000-0000") -> 555-890-1235 | E21: =PROPER(TRIM(RawData!E18)) -> Boston | F21: USA | G21: =RawData!G18 -> 46176 | H21: =RawData!H18 -> 285
A22: =RawData!A11 -> C010 | B22: =PROPER(TRIM(RawData!B11)) -> Jennifer Thomas | C22: =LOWER(TRIM(RawData!C11)) -> jennifer.thomas@email.com | D22: =TEXT(RawData!D11,"000-000-0000") -> 555-567-8902 | E22: =PROPER(TRIM(RawData!E11)) -> Miami | F22: USA | G22: =RawData!G11 -> 46164 | H22: =RawData!H11 -> 275
A23: =RawData!A34 -> C033 | B23: =PROPER(TRIM(RawData!B34)) -> Jennifer Carter | C23: =LOWER(TRIM(RawData!C34)) -> jennifer.carter@email.com | D23: =TEXT(RawData!D34,"000-000-0000") -> 555-678-9024 | E23: =PROPER(TRIM(RawData!E34)) -> Atlanta | F23: USA | G23: =RawData!G34 -> 46215 | H23: =RawData!H34 -> 275
A24: =RawData!A30 -> C029 | B24: =PROPER(TRIM(RawData!B30)) -> Dorothy Green | C24: =LOWER(TRIM(RawData!C30)) -> dorothy.green@email.com | D24: =TEXT(RawData!D30,"000-000-0000") -> 555-456-7802 | E24: =PROPER(TRIM(RawData!E30)) -> Portland | F24: USA | G24: =RawData!G30 -> 46205 | H24: =RawData!H30 -> 265
A25: =RawData!A2 -> C001 | B25: =PROPER(TRIM(RawData!B2)) -> John Smith | C25: =LOWER(TRIM(RawData!C2)) -> john.smith@email.com | D25: =TEXT(RawData!D2,"000-000-0000") -> 555-123-4567 | E25: =PROPER(TRIM(RawData!E2)) -> New York | F25: USA | G25: =RawData!G2 -> 46143 | H25: =RawData!H2 -> 250
A26: =RawData!A22 -> C021 | B26: =PROPER(TRIM(RawData!B22)) -> Karen Allen | C26: =LOWER(TRIM(RawData!C22)) -> karen.allen@email.com | D26: =TEXT(RawData!D22,"000-000-0000") -> 555-012-3457 | E26: =PROPER(TRIM(RawData!E22)) -> Phoenix | F26: USA | G26: =RawData!G22 -> 46185 | H26: =RawData!H22 -> 240
A27: =RawData!A36 -> C035 | B27: =PROPER(TRIM(RawData!B36)) -> Patricia Perez | C27: =LOWER(TRIM(RawData!C36)) -> patricia.perez@email.com | D27: =TEXT(RawData!D36,"000-000-0000") -> 555-789-0135 | E27: =PROPER(TRIM(RawData!E36)) -> Charlotte | F27: USA | G27: =RawData!G36 -> 46220 | H27: =RawData!H36 -> 230
A28: =RawData!A14 -> C013 | B28: =PROPER(TRIM(RawData!B14)) -> Patricia White | C28: =LOWER(TRIM(RawData!C14)) -> patricia.white@email.com | D28: =TEXT(RawData!D14,"000-000-0000") -> 555-678-9013 | E28: =PROPER(TRIM(RawData!E14)) -> Dallas | F28: USA | G28: =RawData!G14 -> 46169 | H28: =RawData!H14 -> 225
A29: =RawData!A26 -> C025 | B29: =PROPER(TRIM(RawData!B26)) -> Lisa Wright | C29: =LOWER(TRIM(RawData!C26)) -> lisa.wright@email.com | D29: =TEXT(RawData!D26,"000-000-0000") -> 555-234-5681 | E29: =PROPER(TRIM(RawData!E26)) -> Austin | F29: USA | G29: =RawData!G26 -> 46195 | H29: =RawData!H26 -> 220
A30: =RawData!A7 -> C006 | B30: =PROPER(TRIM(RawData!B7)) -> Emily Miller | C30: =LOWER(TRIM(RawData!C7)) -> emily.miller@email.com | D30: =TEXT(RawData!D7,"000-000-0000") -> 555-345-6790 | E30: =PROPER(TRIM(RawData!E7)) -> Los Angeles | F30: USA | G30: =RawData!G7 -> 46154 | H30: =RawData!H7 -> 210
A31: =RawData!A38 -> C037 | B31: =PROPER(TRIM(RawData!B38)) -> Linda Turner | C31: =LOWER(TRIM(RawData!C38)) -> linda.turner@email.com | D31: =TEXT(RawData!D38,"000-000-0000") -> 555-890-1246 | E31: =PROPER(TRIM(RawData!E38)) -> Nashville | F31: USA | G31: =RawData!G38 -> 46225 | H31: =RawData!H38 -> 210
A32: =RawData!A24 -> C023 | B32: =PROPER(TRIM(RawData!B24)) -> Betty Hernandez | C32: =LOWER(TRIM(RawData!C24)) -> betty.hernandez@email.com | D32: =TEXT(RawData!D24,"000-000-0000") -> 555-123-4569 | E32: =PROPER(TRIM(RawData!E24)) -> San Diego | F32: USA | G32: =RawData!G24 -> 46190 | H32: =RawData!H24 -> 200
A33: =RawData!A16 -> C015 | B33: =PROPER(TRIM(RawData!B16)) -> Linda Martin | C33: =LOWER(TRIM(RawData!C16)) -> linda.martin@email.com | D33: =TEXT(RawData!D16,"000-000-0000") -> 555-789-0124 | E33: =PROPER(TRIM(RawData!E16)) -> Seattle | F33: USA | G33: =RawData!G16 -> 46172 | H33: =RawData!H16 -> 195
A34: =RawData!A32 -> C031 | B34: =PROPER(TRIM(RawData!B32)) -> Margaret Baker | C34: =LOWER(TRIM(RawData!C32)) -> margaret.baker@email.com | D34: =TEXT(RawData!D32,"000-000-0000") -> 555-567-8913 | E34: =PROPER(TRIM(RawData!E32)) -> Orlando | F34: USA | G34: =RawData!G32 -> 46210 | H34: =RawData!H32 -> 195
A35: =RawData!A40 -> C039 | B35: =PROPER(TRIM(RawData!B40)) -> Jessica Campbell | C35: =LOWER(TRIM(RawData!C40)) -> jessica.campbell@email.com | D35: =TEXT(RawData!D40,"000-000-0000") -> 555-901-2357 | E35: =PROPER(TRIM(RawData!E40)) -> Raleigh | F35: USA | G35: =RawData!G40 -> 46230 | H35: =RawData!H40 -> 195
A36: =RawData!A9 -> C008 | B36: =PROPER(TRIM(RawData!B9)) -> Lisa Taylor | C36: =LOWER(TRIM(RawData!C9)) -> lisa.taylor@email.com | D36: =TEXT(RawData!D9,"000-000-0000") -> 555-456-7891 | E36: =PROPER(TRIM(RawData!E9)) -> Houston | F36: USA | G36: =RawData!G9 -> 46160 | H36: =RawData!H9 -> 190
A37: =RawData!A28 -> C027 | B37: =PROPER(TRIM(RawData!B28)) -> Barbara Hill | C37: =LOWER(TRIM(RawData!C28)) -> barbara.hill@email.com | D37: =TEXT(RawData!D28,"000-000-0000") -> 555-345-6791 | E37: =PROPER(TRIM(RawData!E28)) -> San Antonio | F37: USA | G37: =RawData!G28 -> 46200 | H37: =RawData!H28 -> 185
A38: =RawData!A3 -> C002 | B38: =PROPER(TRIM(RawData!B3)) -> Mary Johnson | C38: =LOWER(TRIM(RawData!C3)) -> mary.johnson@email.com | D38: =TEXT(RawData!D3,"000-000-0000") -> 555-123-4568 | E38: =PROPER(TRIM(RawData!E3)) -> New York | F38: USA | G38: =RawData!G3 -> 46144 | H38: =RawData!H3 -> 180
A39: =RawData!A20 -> C019 | B39: =PROPER(TRIM(RawData!B20)) -> Nancy Walker | C39: =LOWER(TRIM(RawData!C20)) -> nancy.walker@email.com | D39: =TEXT(RawData!D20,"000-000-0000") -> 555-901-2346 | E39: =PROPER(TRIM(RawData!E20)) -> Denver | F39: USA | G39: =RawData!G20 -> 46180 | H39: =RawData!H20 -> 175
A40: =RawData!A5 -> C004 | B40: =PROPER(TRIM(RawData!B5)) -> Sarah Brown | C40: =LOWER(TRIM(RawData!C5)) -> sarah.brown@email.com | D40: =TEXT(RawData!D5,"000-000-0000") -> 555-234-5679 | E40: =PROPER(TRIM(RawData!E5)) -> Chicago | F40: USA | G40: =RawData!G5 -> 46149 | H40: =RawData!H5 -> 150

Sheet Summary
A1: Customer Data Summary
A2: Total Customers | B2: =COUNTA(CleanData!A:A)-1 -> 39
A3: Total Order Value | B3: =SUM(CleanData!H:H) -> 12015
A4: Average Order Value | B4: =AVERAGE(CleanData!H:H) -> 308.07692
A5: Highest Order Value | B5: =MAX(CleanData!H:H) -> 600
A6: Lowest Order Value | B6: =MIN(CleanData!H:H) -> 150
